<?xml version="1.0"?>


<robot name="onshape">
<link name="carbody">
<visual>
<origin xyz="-0.26977427303791046143 0.76915336027741387781 0.076209680177270658352" rpy="1.4444228065004858179e-15 4.9303806576313232364e-32 -3.141592653589793116" />
<geometry>
<mesh filename="package://cybertruck_description/meshes/carbody/carbody.stl"/>
</geometry>
<material name="carbody_material">
<color rgba="0.43921568627450979783 0.47450980392156860699 0.50196078431372548323 1.0"/>
</material>
</visual>
<collision>
<origin xyz="-0.26977427303791046143 0.76915336027741387781 0.076209680177270658352" rpy="1.4444228065004858179e-15 4.9303806576313232364e-32 -3.141592653589793116" />
<geometry>
<mesh filename="package://cybertruck_description/meshes/carbody/carbody.stl"/>
</geometry>
</collision>
<inertial>
<origin xyz="-5.2098254599286519806e-09 0.00058244025544196276201 0.20254629741490282058" rpy="0 0 0"/>
<mass value="2434.9836614598093547" />
<inertia ixx="504.65065693040685346" ixy="-1.1305046015830380197e-05"  ixz="-1.5282670424912572216e-06" iyy="83.974677916800374078" iyz="-11.9684094140509103" izz="524.63594699690986545" />
</inertial>
</link>

<link name="wheel">
<visual>
<origin xyz="2.2204460492503130808e-16 2.7755575615628913511e-17 -0.054999999999999993339" rpy="-1.570796326794896558 -1.570796326794896558 0" />
<geometry>
<mesh filename="package://cybertruck_description/meshes/wheels/rubber.stl"/>
</geometry>
<material name="rubber_material">
<color rgba="0.30196078431372547213 0.30196078431372547213 0.30196078431372547213 1.0"/>
</material>
</visual>
<collision>
<origin xyz="2.2204460492503130808e-16 2.7755575615628913511e-17 -0.054999999999999993339" rpy="-1.570796326794896558 -1.570796326794896558 0" />
<geometry>
<mesh filename="package://cybertruck_description/meshes/wheels/rubber.stl"/>
</geometry>
</collision>

<!--Use x1 and y1-->
<visual>
<origin xyz="1.1102230246251565404e-16 1.3877787807814456755e-17 -0.054999999999999993339" rpy="-1.570796326794896558 -1.570796326794896558 0" />
<geometry>
<mesh filename="package://cybertruck_description/meshes/wheels/outerrim.stl"/>
</geometry>
<material name="outerrim_material">
<color rgba="0 0 0 1.0"/>
</material>
</visual>

<collision>
<origin xyz="1.1102230246251565404e-16 1.3877787807814456755e-17 -0.054999999999999993339" rpy="-1.570796326794896558 -1.570796326794896558 0" />
<geometry>
<mesh filename="package://cybertruck_description/meshes/wheels/outerrim.stl"/>
</geometry>
</collision>

<!-- New numbers here-->
<visual>
<origin xyz="0 0 -0.054999999999999993339" rpy="-1.570796326794896558 -1.570796326794896558 0" />
<geometry>
<mesh filename="package://cybertruck_description/meshes/wheels/innerrim.stl"/>
</geometry>
<material name="innerrim_material">
<color rgba="0.64705882352941179736 0.64705882352941179736 0.64705882352941179736 1.0"/>
</material>
</visual>


<collision>
<origin xyz="0 0 -0.054999999999999993339" rpy="-1.570796326794896558 -1.570796326794896558 0" />
<geometry>
<mesh filename="package://cybertruck_description/meshes/wheels/innerrim.stl"/>
</geometry>
</collision>

<inertial>
<origin xyz="1.3589014717930336387e-16 2.865589325797537375e-17 -0.014008508764301362895" rpy="0 0 0"/>
<mass value="5.9376908742791583151" />
<inertia ixx="0.032071117109724343874" ixy="3.1503975095023306102e-18"  ixz="-4.7163425796709302253e-18" iyy="0.032071117109724357752" iyz="-1.0261803230676583576e-18" izz="0.051594875950933961894" />
</inertial>
</link>

<joint name="LBACK" type="continuous">
<origin xyz="0.23399999999999998579 0.50241941586136773523 0.041397847235202525629" rpy="1.570796326794896558 -1.3461454173579431407e-15 -1.570796326794896558" />
<parent link="carbody" />
<child link="wheel" />
<axis xyz="0 0 1"/>
<limit effort="1" velocity="20" />
<joint_properties friction="0.0"/>
</joint>

<link name="sensorbar">
<visual>
<origin xyz="0.059597848948836310012 0.030648184454273759425 0" rpy="1.570796326794896558 -4.5048600266772715396e-17 -8.673617379884037398e-19" />
<geometry>
<mesh filename="package://cybertruck_description/meshes/sensor/sensorbar.stl"/>
</geometry>
<material name="sensorbar_material">
<color rgba="0 0 0 1.0"/>
</material>
</visual>
<collision>
<origin xyz="0.059597848948836310012 0.030648184454273759425 0" rpy="1.570796326794896558 -4.5048600266772715396e-17 -8.673617379884037398e-19" />
<geometry>
<mesh filename="package://cybertruck_description/meshes/sensor/sensorbar.stl"/>
</geometry>
</collision>
<inertial>
<origin xyz="-0.00085278634972848349483 -6.3531317178695118075e-05 -0.0024996223686946789089" rpy="0 0 0"/>
<mass value="0.0066396964508632343865" />
<inertia ixx="8.2708913888452691336e-08" ixy="3.9374082852641324845e-09"  ixz="-1.812131423886424547e-08" iyy="6.722671558775725881e-06" iyz="-1.3500110115161905531e-09" izz="6.7724163537762414037e-06" />
</inertial>
</link>

<joint name="rsensor" type="fixed">
<origin xyz="0.12002181200253836391 -0.89500082170772932155 0.10088283596281659438" rpy="-1.6089173531410916329 0.0049632062983683200227 0.12940522343665028515" />
<parent link="carbody" />
<child link="sensorbar" />
<axis xyz="0 0 1"/>
<limit effort="1" velocity="20" />
<joint_properties friction="0.0"/>
</joint>

<link name="sensorbar_2">
<visual>
<origin xyz="0.059597848948836316951 0.030648184454273745547 0" rpy="1.570796326794896558 -1.5937771935536912098e-17 -8.6736173798840335461e-19" />
<geometry>
<mesh filename="package://cybertruck_description/meshes/sensor/sensorbar.stl"/>
</geometry>
<material name="sensorbar_material">
<color rgba="0 0 0 1.0"/>
</material>
</visual>
<collision>
<origin xyz="0.059597848948836316951 0.030648184454273745547 0" rpy="1.570796326794896558 -1.5937771935536912098e-17 -8.6736173798840335461e-19" />
<geometry>
<mesh filename="package://cybertruck_description/meshes/sensor/sensorbar.stl"/>
</geometry>
</collision>
<inertial>
<origin xyz="-0.00085278634972849737261 -6.3531317178705526416e-05 -0.0024996223686946771742" rpy="0 0 0"/>
<mass value="0.0066396964508632343865" />
<inertia ixx="8.2708913888452744275e-08" ixy="3.9374082852641333117e-09"  ixz="-1.8121314238863980772e-08" iyy="6.7226715587757241869e-06" iyz="-1.3500110115160968749e-09" izz="6.7724163537762414037e-06" />
</inertial>
</link>

<joint name="lsensor" type="fixed">
<origin xyz="-0.12002181200253836391 -0.89500082170772898849 0.10088283596281662213" rpy="-1.6089173531410907447 -0.0049632062983683226248 -0.12940522343665034066" />
<parent link="carbody" />
<child link="sensorbar_2" />
<axis xyz="0 0 1"/>
<limit effort="1" velocity="20" />
<joint_properties friction="0.0"/>
</joint>

<link name="wheel_2">

<visual>
<origin xyz="0 0 -0.054999999999999993339" rpy="-1.570796326794896558 -1.570796326794896558 0" />
<geometry>
<mesh filename="package://cybertruck_description/meshes/wheels/rubber.stl"/>
</geometry>
<material name="rubber_material">
<color rgba="0.30196078431372547213 0.30196078431372547213 0.30196078431372547213 1.0"/>
</material>
</visual>
<collision>
<origin xyz="0 0 -0.054999999999999993339" rpy="-1.570796326794896558 -1.570796326794896558 0" />
<geometry>
<mesh filename="package://cybertruck_description/meshes/wheels/rubber.stl"/>
</geometry>
</collision>

<visual>
<origin xyz="0 0 -0.054999999999999993339" rpy="-1.570796326794896558 -1.570796326794896558 0" />
<geometry>
<mesh filename="package://cybertruck_description/meshes/wheels/outerrim.stl"/>
</geometry>
<material name="outerrim_material">
<color rgba="0 0 0 1.0"/>
</material>
</visual>
<collision>
<origin xyz="0 0 -0.054999999999999993339" rpy="-1.570796326794896558 -1.570796326794896558 0" />
<geometry>
<mesh filename="package://cybertruck_description/meshes/wheels/outerrim.stl"/>
</geometry>
</collision>

<visual>
<origin xyz="0 0 -0.054999999999999993339" rpy="-1.570796326794896558 -1.570796326794896558 0" />
<geometry>
<mesh filename="package://cybertruck_description/meshes/wheels/innerrim.stl"/>
</geometry>
<material name="innerrim_material">
<color rgba="0.64705882352941179736 0.64705882352941179736 0.64705882352941179736 1.0"/>
</material>
</visual>
<collision>
<origin xyz="0 0 -0.054999999999999993339" rpy="-1.570796326794896558 -1.570796326794896558 0" />
<geometry>
<mesh filename="package://cybertruck_description/meshes/wheels/innerrim.stl"/>
</geometry>
</collision>
<inertial>
<origin xyz="-6.2361851381479182544e-18 1.089297430533192376e-17 -0.014008508764301362895" rpy="0 0 0"/>
<mass value="5.9376908742791583151" />
<inertia ixx="0.032071117109724329997" ixy="6.2023450968327039518e-18"  ixz="1.0286902923306847666e-18" iyy="0.032071117109724329997" iyz="-3.0649033447830545848e-19" izz="0.051594875950933961894" />
</inertial>
</link>

<joint name="LFRONT" type="continuous">
<origin xyz="0.23399999999999998579 -0.6649815680623489822 0.045063234419993825064" rpy="1.570796326794896558 -1.332267629550186468e-15 -1.570796326794896558" />
<parent link="carbody" />
<child link="wheel_2" />
<axis xyz="0 0 1"/>
<limit effort="1" velocity="20" />
<joint_properties friction="0.0"/>
</joint>

<link name="wheel_3">

<visual>
<origin xyz="0 0 -0.054999999999999993339" rpy="-1.570796326794896558 -1.570796326794896558 0" />
<geometry>
<mesh filename="package://cybertruck_description/meshes/wheels/rubber.stl"/>
</geometry>
<material name="rubber_material">
<color rgba="0.30196078431372547213 0.30196078431372547213 0.30196078431372547213 1.0"/>
</material>
</visual>
<collision>
<origin xyz="0 0 -0.054999999999999993339" rpy="-1.570796326794896558 -1.570796326794896558 0" />
<geometry>
<mesh filename="package://cybertruck_description/meshes/wheels/rubber.stl"/>
</geometry>
</collision>

<visual>
<origin xyz="0 0 -0.054999999999999993339" rpy="-1.570796326794896558 -1.570796326794896558 0" />
<geometry>
<mesh filename="package://cybertruck_description/meshes/wheels/outerrim.stl"/>
</geometry>
<material name="outerrim_material">
<color rgba="0 0 0 1.0"/>
</material>
</visual>
<collision>
<origin xyz="0 0 -0.054999999999999993339" rpy="-1.570796326794896558 -1.570796326794896558 0" />
<geometry>
<mesh filename="package://cybertruck_description/meshes/wheels/outerrim.stl"/>
</geometry>
</collision>

<visual>
<origin xyz="0 0 -0.054999999999999993339" rpy="-1.570796326794896558 -1.570796326794896558 0" />
<geometry>
<mesh filename="package://cybertruck_description/meshes/wheels/innerrim.stl"/>
</geometry>
<material name="innerrim_material">
<color rgba="0.64705882352941179736 0.64705882352941179736 0.64705882352941179736 1.0"/>
</material>
</visual>
<collision>
<origin xyz="0 0 -0.054999999999999993339" rpy="-1.570796326794896558 -1.570796326794896558 0" />
<geometry>
<mesh filename="package://cybertruck_description/meshes/wheels/innerrim.stl"/>
</geometry>
</collision>
<inertial>
<origin xyz="-6.2361848359611121551e-18 1.0885944194975171098e-17 -0.014008508764301362895" rpy="0 0 0"/>
<mass value="5.9376908742791583151" />
<inertia ixx="0.032071117109724399385" ixy="8.3713350159878664522e-19"  ixz="1.0286906400690397168e-18" iyy="0.032071117109724350813" iyz="-3.1704737612245841543e-19" izz="0.051594875950933961894" />
</inertial>
</link>

<joint name="RFRONT" type="continuous">
<origin xyz="-0.23399999999999998579 -0.6649815680623489822 0.045063234419993936086" rpy="-1.570796326794896558 -1.3582884816897784238e-15 -1.570796326794896558" />
<parent link="carbody" />
<child link="wheel_3" />
<axis xyz="0 0 1"/>
<limit effort="1" velocity="20" />
<joint_properties friction="0.0"/>
</joint>

<link name="wheel_4">

<visual>
<origin xyz="0 -1.3877787807814456755e-17 -0.054999999999999993339" rpy="-1.570796326794896558 -1.570796326794896558 0" />
<geometry>
<mesh filename="package://cybertruck_description/meshes/wheels/rubber.stl"/>
</geometry>
<material name="rubber_material">
<color rgba="0.30196078431372547213 0.30196078431372547213 0.30196078431372547213 1.0"/>
</material>
</visual>
<collision>
<origin xyz="0 -1.3877787807814456755e-17 -0.054999999999999993339" rpy="-1.570796326794896558 -1.570796326794896558 0" />
<geometry>
<mesh filename="package://cybertruck_description/meshes/wheels/rubber.stl"/>
</geometry>
</collision>

<visual>
<origin xyz="0 0 -0.054999999999999993339" rpy="-1.570796326794896558 -1.570796326794896558 0" />
<geometry>
<mesh filename="package://cybertruck_description/meshes/wheels/outerrim.stl"/>
</geometry>
<material name="outerrim_material">
<color rgba="0 0 0 1.0"/>
</material>
</visual>
<collision>
<origin xyz="0 0 -0.054999999999999993339" rpy="-1.570796326794896558 -1.570796326794896558 0" />
<geometry>
<mesh filename="package://cybertruck_description/meshes/wheels/outerrim.stl"/>
</geometry>
</collision>

<visual>
<origin xyz="0 0 -0.054999999999999993339" rpy="-1.570796326794896558 -1.570796326794896558 0" />
<geometry>
<mesh filename="package://cybertruck_description/meshes/wheels/innerrim.stl"/>
</geometry>
<material name="innerrim_material">
<color rgba="0.64705882352941179736 0.64705882352941179736 0.64705882352941179736 1.0"/>
</material>
</visual>
<collision>
<origin xyz="0 0 -0.054999999999999993339" rpy="-1.570796326794896558 -1.570796326794896558 0" />
<geometry>
<mesh filename="package://cybertruck_description/meshes/wheels/innerrim.stl"/>
</geometry>
</collision>
<inertial>
<origin xyz="-6.2361852559968973616e-18 5.4186941231292382074e-18 -0.014008508764301362895" rpy="0 0 0"/>
<mass value="5.9376908742791583151" />
<inertia ixx="0.03207111710972437163" ixy="-3.7819973611508903677e-18"  ixz="1.0286901202560229468e-18" iyy="0.032071117109724357752" iyz="1.0619700477622371871e-18" izz="0.051594875950933961894" />
</inertial>
</link>

<joint name="RBACK" type="continuous">
<origin xyz="-0.23399999999999998579 0.50241941586136773523 0.041397847235202483995" rpy="-1.570796326794896558 -1.3600232051657552309e-15 -1.570796326794896558" />
<parent link="carbody" />
<child link="wheel_4" />
<axis xyz="0 0 1"/>
<limit effort="1" velocity="20" />
<joint_properties friction="0.0"/>
</joint>


</robot>
