<?xml version="1.0"?>
<robot xmlns:xacro="http://ros.org/wiki/xacro" name="cybertruck_robot">

    <!-- Macro for defining a wheel link -->
    <xacro:macro name="wheel_link" params="suffix x y z x1 y1 r p yw ixx ixy ixz iyy iyz izz x2 y2 z2 i_xyz_x i_xyz_y i_xyz_z">
        

         <link name="wheel_${suffix}"> 
            <visual>
                <origin xyz="${x} ${y} ${z}" rpy="${r} ${p} ${yw}" />
                <geometry>
                    <mesh filename="package://cybertruck_description/meshes/wheels/rubber.stl"/>
                </geometry>
                <material name="rubber_material">
                    <color rgba="0.30196078431372547213 0.30196078431372547213 0.30196078431372547213 1.0"/>
                </material>
            </visual>

            <collision>
                <origin xyz="${x} ${y} ${z}" rpy="${r} ${p} ${yw}" />
                <geometry>
                    <mesh filename="package://cybertruck_description/meshes/wheels/rubber.stl"/>
                </geometry>
            </collision>

            <!--Make sure use x1 and y1 but same z-->
            <visual>
                <origin xyz="${x1} ${y1} ${z}" rpy="${r} ${p} ${yw}" />
                <geometry>
                    <mesh filename="package://cybertruck_description/meshes/wheels/outerrim.stl"/>
                </geometry>
                <material name="outerrim_material">
                    <color rgba="0 0 0 1.0"/>
                </material>
            </visual>

            <collision>
                <origin xyz="${x1} ${y1} ${z}" rpy="${r} ${p} ${yw}" />
                <geometry>
                    <mesh filename="package://cybertruck_description/meshes/wheels/outerrim.stl"/>
                </geometry>
            </collision>

            <!--New numbers here-->
            <visual>
                <origin xyz="${x2} ${y2} ${z2}" rpy="${r} ${p} ${yw}" />
                <geometry>
                    <mesh filename="package://cybertruck_description/meshes/wheels/innerrim.stl"/>
                </geometry>
                <material name="innerrim_material">
                    <color rgba="0.64705882352941179736 0.64705882352941179736 0.64705882352941179736 1.0"/>
                </material>
            </visual>

            <collision>
                <origin xyz="${x2} ${y2} ${z2}" rpy="${r} ${p} ${yw}" />
                <geometry>
                    <mesh filename="package://cybertruck_description/meshes/wheels/innerrim.stl"/>
                </geometry>
            </collision>

            <inertial>
                <origin xyz="${i_xyz_x} ${i_xyz_y} ${i_xyz_z}" rpy="0 0 0"/>
                <mass value="5.9376908742791583151" />
                <inertia ixx="${ixx}" ixy="${ixy}"  ixz="${ixz}" iyy="${iyy}" iyz="${iyz}" izz="${izz}" />
            </inertial>    
        </link> 
    </xacro:macro> 

    <!-- Macro for defining a wheel joint -->
    <xacro:macro name="wheel_joint" params="name parent child x y z r p yw">
        <joint name="${name}" type="continuous">
            <parent link="${parent}" />
            <child link="${child}" />
            <origin xyz="${x} ${y} ${z}" rpy="${r} ${p} ${yw}" />
            <axis xyz="0 0 1"/>
            <limit effort="1" velocity="20" />
            <dynamics damping="0.5" friction="0.1"/>
        </joint>
    </xacro:macro>





</robot>
